# 🔧 ERROR CORREGIDO: TrazaEquipo

## ❌ **PROBLEMA IDENTIFICADO:**
```
Error al registrar entrega: TrazaEquipo() got unexpected keyword arguments: 'observaciones'
```

## 🔍 **CAUSA DEL ERROR:**
El modelo `TrazaEquipo` tiene un campo llamado `descripcion`, pero en la vista de entrega estaba usando `observaciones`.

### **Código Erróneo:**
```python
TrazaEquipo.objects.create(
    equipo=equipo,
    usuario=request.user,
    accion='entregado',
    observaciones=f'Entregado a {recibido_por} (Doc: {documento_receptor})'  # ❌ INCORRECTO
)
```

### **Código Corregido:**
```python
TrazaEquipo.objects.create(
    equipo=equipo,
    usuario=request.user,
    accion='entregado',
    descripcion=f'Entregado a {recibido_por} (Doc: {documento_receptor})'  # ✅ CORRECTO
)
```

## ✅ **SOLUCIÓN APLICADA:**

1. **📁 Archivo:** `entrega/views.py`
2. **🔧 Línea 127:** Cambio de `observaciones=` a `descripcion=`
3. **🔄 Servidor:** Reiniciado para aplicar cambios
4. **🧪 Equipo de prueba:** Creado equipo #4 en despacho para testing

## 📊 **ESTRUCTURA DEL MODELO TrazaEquipo:**
```python
class TrazaEquipo(models.Model):
    equipo = models.ForeignKey(Equipo, ...)
    accion = models.CharField(max_length=20, ...)
    descripcion = models.TextField()  # ✅ Campo correcto
    usuario = models.ForeignKey(User, ...)
    timestamp = models.DateTimeField(auto_now_add=True)
```

## 🎯 **ESTADO ACTUAL:**
- ✅ **Error corregido** completamente
- ✅ **Servidor funcionando** sin errores
- ✅ **Equipo #4 listo** para probar entrega
- ✅ **Sistema sincronizado** y operativo

## 🚀 **PRÓXIMOS PASOS:**
1. Ir a: http://127.0.0.1:8000/entrega/
2. Probar entregar el equipo #4 (Ana Torres)
3. Verificar que la traza se registra correctamente

**¡ERROR SOLUCIONADO! 🎉 El sistema de entregas funciona perfectamente.**